<?xml version="1.0" ?>
<!-- =================================================================================== -->
<!-- |    This document was autogenerated by xacro from greeterbotPtu.xacro            | -->
<!-- |    EDITING THIS FILE BY HAND IS NOT RECOMMENDED                                 | -->
<!-- =================================================================================== -->
<robot name="lewis" xmlns:controller="http://playerstage.sourceforge.net/gazebo/xmlschema/#controller" xmlns:interface="http://playerstage.sourceforge.net/gazebo/xmlschema/#interface" xmlns:sensor="http://playerstage.sourceforge.net/gazebo/xmlschema/#sensor" xmlns:xacro="http://playerstage.sourceforge.net/gazebo/xmlschema/#interface">
  <material name="black">
    <color rgba="0 0 0 1"/>
  </material>
  <material name="gray">
    <color rgba=".8 .8 .8 1"/>
  </material>
  <link name="base_link">
    <inertial>
      <mass value="1"/>
      <inertia ixx="100" ixy="0" ixz="0" iyy="100" iyz="0" izz="100"/>
      <origin/>
    </inertial>
    <visual>
      <origin xyz="0 0 .15"/>
      <geometry>
        <cylinder length="0.3" radius="0.26"/>
      </geometry>
      <material name="lewisred">
        <color rgba="1 0 0 1"/>
      </material>
    </visual>
    <collision>
      <origin xyz="0 0 .15"/>
      <geometry>
        <cylinder length="0.3" radius="0.26"/>
      </geometry>
    </collision>
  </link>
  <link name="ptu_base">
    <inertial>
      <mass value="1"/>
      <inertia ixx="100" ixy="0" ixz="0" iyy="100" iyz="0" izz="100"/>
      <origin/>
    </inertial>
    <visual>
      <origin xyz="0 0.015 0"/>
      <geometry>
        <box size="0.04 .07 .05"/>
      </geometry>
      <material name="black"/>
    </visual>
    <collision>
      <origin xyz="0 0.015 0"/>
      <geometry>
        <box size="0.04 .07 .05"/>
      </geometry>
    </collision>
  </link>
  <joint name="toptubase" type="fixed">
    <origin xyz="0 -0.0075 .0275"/>
    <parent link="base_link"/>
    <child link="ptu_base"/>
  </joint>
  <link name="ptu_piece">
    <inertial>
      <mass value="1"/>
      <inertia ixx="100" ixy="0" ixz="0" iyy="100" iyz="0" izz="100"/>
      <origin/>
    </inertial>
    <visual>
      <origin/>
      <geometry>
        <box size="0.04 .04 .06"/>
      </geometry>
      <material name="black"/>
    </visual>
    <collision>
      <origin/>
      <geometry>
        <box size="0.04 .04 .06"/>
      </geometry>
    </collision>
  </link>
  <joint name="pan" type="continuous">
    <origin xyz="0 0 .055"/>
    <axis xyz="0 0 1"/>
    <parent link="ptu_base"/>
    <child link="ptu_piece"/>
  </joint>
  <link name="ptu_mount">
    <inertial>
      <mass value="1"/>
      <inertia ixx="100" ixy="0" ixz="0" iyy="100" iyz="0" izz="100"/>
      <origin/>
    </inertial>
    <visual>
      <origin/>
      <geometry>
        <box size="0.04 .27 .03"/>
      </geometry>
      <material name="gray"/>
    </visual>
    <collision>
      <origin/>
      <geometry>
        <box size="0.04 .27 .03"/>
      </geometry>
    </collision>
  </link>
  <joint name="tilt" type="continuous">
    <origin xyz="0 0 .065"/>
    <axis xyz="0 -1 0"/>
    <parent link="ptu_piece"/>
    <child link="ptu_mount"/>
  </joint>
</robot>

